Workbook
Name _Hlk4331660: [1]Үйлд.З!#REF!
Name СТР_1: #REF!
Name СТР_2: #REF!

Sheet ҮЙЛДВЭР ЯВУУЛДАГ
A4: ҮЙЛДВЭРЛЭЛТИЙН ҮЙЛ АЖИЛЛАГАА
A5: ЯВУУЛЖ БУЙ КОМПАНИЙН НЭРС
B7: Хамаарах компанийн нэрс | C7: Хариуцсан аудиторын нэр
A8: 1 | B8: Эрдэнэт Үйлдвэр ТӨҮГ | C8: Н.Мөнхжаргал
A9: 2 | B9: Дарханы Төмөрлөгийн Үйлдвэр ТӨХК | C9: А.Бямбадорж
A10: 3 | B10: Цемент шохой ТӨХК | C10: Д.Чулуунбат
A11: 4 | B11: Эрдэнэс критикал менералс ТӨҮГ | C11: Сү.Гэрэлмаа
A12: 5 | B12: Эрдэнэс Алт Ресурс ХХК | C12: Г.Батхонгор
A13: 6 | B13: Эрдэнэс таван толгой ХК | C13: Н.Мөнхжаргал
A14: 7 | B14: Гашуун Сухайт Автозам ХХК | C14: Г.Батхонгор
A15: 8 | B15: Багануур ХК | C15: Ц.Ядамцоо
A16: 9 | B16: Шивээ овоо ХК | C16: Б.Мөнгөнцэцэг

Sheet ЗЭЭЛЭЭР САНХҮҮЖДЭГ
A3: ЗЭЭЛЭЭР САНХҮҮЖДЭГ КОМПАНИЙН НЭРС
A5: 1 | B5: "Эрдэнэс ҮТП" ХХК | C5: Д.Эрдэнэ-Очир
A6: 2 | B6: "Монгол газрын тос боловсруулах үйлдвэр" ХХК | C6: Ж.Хашбат
A7: 3 | B7: "Эрдэнэс Оюу толгой" ХХК | C7: Б.Уранзаяа
A8: 4 | B8: "Мон Атом" ХХК | C8: Сү.Гэрэлмаа
A9: 5 | B9: "Эрдэнэс Метан" ХХК | C9: Д.Бямбадорж
A10: 6 | B10: "Эрдэнэс Баянбогд" ХХК | C10: Д.Бямбадорж
A11: 7 | B11: "Чингис хаан үндэсний баялгийн сан" ХХК | C11: Сү.Гэрэлмаа

Sheet тайланд тусгах АС нэгтгэл-3.01
S1: Дотоод аудитын БА-2025/11 дугаартай тайлангийн хавсралт №1
A3: НЭГДЛИЙН ОХИН ХАРААТ КОМПАНИД ХИЙСЭН АУДИТЫН АСУУДЛЫН НЭГТГЭЛИЙН ХАРИУ ТАЙЛБАР
R5: /сая төгрөг/
A6: № | B6: Илэрсэн асуудлын товч утга | C6: Санхүүгийн тайлангийн үзүүлэлт | E6: Авлага, өр төлбөр | G6: Санхүүгийн шинжилгээний үр дүн | I6: Уулын ажил | K6: ЭЗҮҮ | M6: Хөрөнгө оруулалт | O6: Шилэн данс | Q6: Нийт дүн | S6: Хариу тайлбар
C7: Асуудлын тоо | D7: Мөнгөн дүн | E7: Асуудлын тоо | F7: Мөнгөн дүн | G7: Асуудлын тоо | H7: Мөнгөн дүн | I7: Асуудлын тоо | J7: Мөнгөн дүн | K7: Асуудлын тоо | L7: Мөнгөн дүн | M7: Асуудлын тоо | N7: Мөнгөн дүн | O7: Асуудлын тоо | P7: Мөнгөн дүн | Q7: Асуудлын тоо | R7: Мөнгөн дүн
A8: 1 | B8: Эрдэнэт Үйлдвэр ТӨҮГ | C8: =+C9+C10 -> 1 | D8: =+D9+D10 -> 176584 | E8: =+E9+E10 -> 0 | F8: =+F9+F10 -> 0 | G8: =+G9+G10 -> 0 | H8: =+H9+H10 -> 0 | I8: =+I9+I10 -> 0 | J8: =+J9+J10 -> 0 | ... R8: =+R9+R10 -> 176584
A9: 1.1 | B9: Санхүүгийн бүртгэлд шилжүүлсэн үндсэн хөрөнгийн дүнг татвар ногдуулах зорилгоор үйлдвэрийн орлогоор бүртгэсэн ба үүний улмаас үйлдвэрийн орлого 84,087.6 сая төгрөгөөр, үйлдвэрийн зардал 92,496.4 сая төгрөгөөр тус тус үндэслэлгүйгээр нэмэгдсэн байна. /Шилжүүлсэн хөрөнгийг үндсэн хөрөнгө бор/шилжүүлсний гарзаар 92,496.4 сая төгрөгөөр бүртгэсэн/ | C9: 1 | D9: 176584 | Q9: 1 | R9: 176584 | S9: Нэмэгдсэн өртгийн албан татварын тухай хуулийн 13.9-д "Бараа, ажил, үйлчилгээг үйлдвэрлэлийн дотоод эргэлтэд ашигласнаас бусад хэлбэрээр бусдад үнэ төлбөргүй шилжүүлсэн буюу хувийнхаа хэрэгцээнд ашигласан бол нэмэгдсэн өртгийн албан татвараас чөлөөлөхгүй", 4.1.2-т ""бараа" гэж мөнгөн хөрөнгөнөөс бусад бүх төрлийн хөрөнгийг" гэж тус тус заасны дагуу орлогоор хүлээн зөвшөөрч бүртгэсэн.
A10: 1.4 | B10: Шилэн дансны цахим хуудсанд эхний хагас жилийн хугацаанд 91 мэдээллээс 85 мэдээллийг хугацаанд нь, 6 мэдээллийг хугацаа хоцроон байршуулж, 85 мэдээллээс 8 мэдээллийг мэдээлэл байхгүйгээр тайлагнасан байна. Эхний хагас жилийн байдлаар “Төрийн өмчийн аж ахуйн нэгж байгууллагын зорилтот түвшин, гүйцэтгэл, хэтрэлт хэмнэлтийн шалтгаан тайлбарын хамт” гэсэн хэсэгт “мэдээлэл байхгүй” гэж оруулсан тул нийтэд мэдээлсэн мэдээлэлтэй тулган баталгаажуулах боломжгүй байна. | O10: 1 | Q10: 1 | R10: 0 | S10: Үйлдвэрийн газрын 2025 оны хөрөнгө оруулалтын төлөвлөгөөг баталсан "Эрдэнэс Монгол" ХХК-ийн ТУЗ-ын тогтоол 2024 оны 12 дугаар сарын 19-ний өдрөөр гарсан боловч эцэслэн баталгаажуулалт нь 2025 оны 01 дүгээр сарын 10-ны өдрөөс хойш буюу 2025 оны 02 дугаар сарын 10-ны өдөр хийгдсэн. Тухайн баталгаажуулалт хийгдсэн даруйд хөрөнгийн зардал, хөрөнгө оруулалтын төсөл, арга хэмжээний төлөвлөгөө, концессын зүйлийн жагсаалтын төлөвлөгөө болон 1-р сарын гүйцэтгэлийг шилэн дансны цахим системд байршуулсан болно. Үйлдвэрийн газрын худалдан авах ажиллагааны төлөвлөгөө нь батлагдсан хөрөнгө оруулалтын төлөвлөгөө, зорилтот түвшин, бизнес төлөвлөгөөнд үндэслэн боловсруулагддаг. Хөрөнгө оруулалтын төлөвлөгөө, зорилтот түвшин, бизнес төлөвлөгөө хугацаа хоцорч батлагдсантай холбоотойгоор хойшлогдож боловсруулагдаж, батлагдсан. ХАА-ны төлөвлөгөө tender.gov.mn-д нийтлэгдсэн даруйд шилэн дансны цахим системд байршуулсан болно. Үйлдвэрийн газрын 2024 оны зорилтот түвшний гүйцэтгэл нь жилийн эцсийн санхүүгийн тайлан эцэслэн гарсны дараа албажиж гардаг тул үүнийг хуулийн хугацаанд байршуулах боломжгүй юм. Иймд бид хавсралтаар албан ёсны мэдээллийг нөхөж оруулсан болно.
A11: 2 | B11: Дарханы Төмөрлөгийн Үйлдвэр ТӨХХК | C11: =+C12+C13 -> 0 | D11: =+D12+D13 -> 0 | E11: =+E12+E13 -> 0 | F11: =+F12+F13 -> 0 | G11: =+G12+G13 -> 0 | H11: =+H12+H13 -> 0 | I11: =+I12+I13 -> 0 | J11: =+J12+J13 -> 0 | ... R11: =+R12+R13 -> 49314.8
A12: 2.1 | B12: Тус компанийн 2025 оны эхний хагас жилийн санхүүгийн тайланд тусгагдсан санхүүгийн мэдээлэл ХЭХ-д танилцуулсан мэдээлэлээс нийт орлого 4,883.8 сая төгрөгөөр дутуу, зардал 2,525.9 сая төгрөгөөр илүү илэрхийлсэн байна | K12: 1 | L12: 7418.4 | Q12: 1 | R12: 7418.4 | S12: Дарханы төмөрлөгийн үйлдвэр ХХК нь төсөв, төлөвлөгөө, гүйцэтгэлийг тайланг боловсруулахдаа Эрдэнэс Монгол ХХК-аас ирүүлсэн "Нэгдлийн хуулийн этгээдийн зорилтот түвшин, төсөв, хөрөнгө оруулалтын төлөвлөгөө, тодотголын төсөл боловсруулах аргачлал"-ийг мөрдлөг болгон тайлагнадаг. Дарханы төмөрлөгийн үйлдвэрийн 2025 оны хагас жилийн ХЭХ-ийн танилцуулгад нийт орлогод бүтээгдэхүүний борлуулалтын орлого 282,389.9 тэрбум төгрөг, түрээсийн орлого 257.9 сая төгрөг, хүүгийн орлого 847.5 сая төгрөг, бусад орлого 413.3 сая төгрөг нийт орлогыг 284.9 тэрбум төгрөгөөр танилцуулсан. Гадаад валютын ханшийн олз 4,883.8 сая төгрөгийг үйл ажиллагааны бус ашгаар зорилтот түвшинд оруулж нийт орлогод оруулаагүй. Нийт зардлыг үйлдвэрлэл, үйл ажиллагааны нийт зардлаар буюу 244,857.9 сая төгрөгөөр танилцуулсан бөгөөд үүнээс борлуулсан бүтээгдэхүүний өртөг 242,374.0 сая төгрөг, бэлэн бүтээгдэхүүнрүү шилжих өртөг 2,483.9 сая төгрөг байна. Тус аргачлалын маягт№1-ын дагуу эдийн засгийн үндсэн үзүүлэлт, зорилтот түвшнийг бэлтгэн үүний дагуу тоон үзүүлэлтүүдийг ХЭХ-д танилцуулсан.
A13: 2.2 | B13: Шилэн дансны цахим хуудсанд эхний хагас жилийн хугацаанд 91 мэдээллээс 78 мэдээллийг хугацаанд нь, 4 мэдээллийг хугацаа хоцроон байршуулж, 9 мэдээллийг мэдээлэл байхгүйгээр тайлагнасан байна. | O13: 2 | P13: 41896.4 | Q13: 2 | R13: 41896.4 | S13: Дарханы төмөрлөгийн үйлдвэр ХХК-ийн эдийн засгийн үндсэн үзүүлэлт, зорилтот түвшин, хөрөнгө оруулалтын төлөвлөгөө, төсөв нь 2024 оны 12 дугаар сарын 19-ны өдөр Эрдэнэс Монгол ХХК-ийн ТУЗ-ийн хурлаар орсон. Төсөв, хөрөнгө оруулалтын тогтоол 2025 оны 01 дүгээр сарын 20-ны өдөр албажин ирсэн. Шилэн дансны мэдээллийг жил бүрийн 01 дүгээр сарын 10-ны дотор оруулах заалттай боловч төсөв төлөвлөгөө баталгаажин ирээгүйн улмаас мэдээллийг хугацаанд нь оруулаагүй хугацаа хоцроосон. 2025 оны төсөв, хөрөнгө оруулалтын төлөвлөгөөнд 2025 оны эхний хагас жилийн байдлаар өөрчлөлт ороогүй тул төлөвлөгөөнд өөрчлөлт ороогүйгээр тайлагнасан.
A14: 3 | B14: Цемент шохой ТӨХХК | C14: =C15+C16 -> 0 | D14: =D15+D16 -> 0 | E14: =E15+E16 -> 0 | F14: =F15+F16 -> 0 | G14: =G15+G16 -> 0 | H14: =H15+H16 -> 0 | I14: =I15+I16 -> 0 | J14: =J15+J16 -> 0 | ... R14: =R15+R16 -> 407667.4
A15: 3.1 | B15: 2025 оны эхний хагас жилийн үйл ажиллагааны нийт зардлын дүн ХЭХ-д танилцуулсан мэдээлэл, ТТ-02-ийн мэдээлэл зөрүүтэй байна | K15: 1 | L15: 1444.5 | Q15: 1 | R15: 1444.5 | S15: 2 удаа мэдэгдсэн ирүүлээгүй.
A16: 3.2 | B16: Шилэн дансны цахим хуудсанд эхний хагас жилийн хугацаанд 91 мэдээллээс 65 мэдээллийг хугацаанд нь, 6 мэдээллийг хугацаа хоцроон байршуулж, 20 мэдээллийг мэдээлэл байхгүйгээр тайлагнасан байна. Эхний хагас жилийн байдлаар санхүүгийн тайлангаас Шилэн дансны мэдээлэлд орлого 620.1 сая төгрөг, авлага 46,870.2 сая төгрөгөөр илүү, үйл ажиллагааны зардал 4,231.2 сая төгрөг, өглөг 354,501.4 сая төгрөгөөр дутуу тайлагнасан байна. | O16: 2 | P16: 406222.9 | Q16: 2 | R16: 406222.9
A17: 4 | B17: Эрдэнэс критикал менералс ТӨҮГ | C17: =+C18 -> 0 | D17: =+D18 -> 0 | E17: =+E18 -> 0 | F17: =+F18 -> 0 | G17: =+G18 -> 0 | H17: =+H18 -> 0 | I17: =+I18 -> 0 | J17: =+J18 -> 0 | ... R17: =+R18 -> 94723.5
A18: 4.1 | B18: Шилэн дансны цахим хуудсанд эхний хагас жилийн хугацаанд 91 мэдээллээс 82 мэдээллийг хугацаанд нь, 3 мэдээллийг хугацаа хоцроон байршуулж, 6 мэдээллийг мэдээлэл байхгүйгээр тайлагнасан байна. Эхний хагас жилийн байдлаар санхүүгийн тайлангаас Шилэн дансны мэдээлэлд нийт орлого 4,611.4 сая төгрөг, өр төлбөр 47,616.1 сая төгрөг, авлага 19,294.4 сая төгрөг, хөрөнгө оруулалт 6,575.2 сая төгрөгөөр дутуу, үйл ажиллагааны зардал 16,626.4 сая төгрөгөөр илүү тайлагнасан байна. | O18: 2 | P18: 94723.5 | Q18: 2 | R18: 94723.5 | S18: """Эрдэнэс критикал минералс"" ТӨҮГ нь тухайн тайлант хугацааны (сар бүр) мэдээллийг шилэн дансанд дараа сарын 8-ны өдрийн дотор байршуулж байна. Дээрх хугацаанд манай байгууллагын орлогын тайлан, төсвийн гүйцэтгэл, ашиг алдагдлын тайлан бүрэн гарах боломжгүй байдаг тул тухайн тайлант хугацааны орлого, өр төлбөр, авлага, хөрөнгө оруулалт, зардал, ашиг алдагдал зэргийг урьдчилан тооцоолж хүлээгдэж буй гүйцэтгэлээр мэдээллийг байршуулж байгаа болно. Жич : төсвийн байгууллага, төрийн сантай адил сар бүрийн эцэст төсвийн хэлбэлзэл татаж тайлан гаргах боломжгүй, мөн санхүүгийн тайланг сар бүр гаргадаггүй болно. "
A19: 5 | B19: Эрдэнэс Алт Ресурс ХХК | C19: =+C20+C21+C22 -> 1 | D19: =+D20+D21+D22 -> 39887.1 | E19: =+E20+E21+E22 -> 0 | F19: =+F20+F21+F22 -> 0 | G19: =+G20+G21+G22 -> 0 | H19: =+H20+H21+H22 -> 0 | I19: =+I20+I21+I22 -> 0 | J19: =+J20+J21+J22 -> 0 | ... R19: =+R20+R21+R22 -> 75213
A20: 5.1 | B20: Тус компани нь 2025 оны эхний хагас жилийн санхүүгийн тайлангаас ХЭХ-д танилцуулсан мэдээлэлээс орлого 2,321.3 сая төгрөгөөр дутуу илэрхийлсэн байна | K20: 1 | L20: 2321.3 | Q20: 1 | R20: 2321.3 | S20: орлогыг дутуу илэрхийлсэн мэдээлэл байхгүй 2,321.3 сая төгрөгийг яаж гаргасан талаар мэдээлэл авах хэрэгтэй байна.
A21: 5.2 | B21: Тус компани нь 2025 оны эхний хагас жилийн санхүүгийн тайлангаас ХЭХ-д танилцуулсан мэдээлэлээс нийт хөрөнгө 2,343.2 сая төгрөгөөр, өр төлбөр 37,543.9 сая төгрөгөөр зөрүүтэй илэрхийлсэн байна. | C21: 1 | D21: 39887.1 | Q21: 1 | R21: 39887.1 | S21: мэдээллийн дэлгэрэнгүйтэй танилцах шаардлагаатай байна.
A22: 5.3 | B22: Шилэн дансны цахим хуудсанд эхний хагас жилийн хугацаанд 91 мэдээллээс 79 мэдээллийг хугацаанд нь, 6 мэдээллийг хугацаа хоцроон байршуулж, 6 мэдээллийг мэдээлэл байхгүйгээр тайлагнасан байна. Эхний хагас жилийн байдлаар санхүүгийн тайлангаас Шилэн данс мэдээлэл орлого 16.0 сая төгрөг, авлага 856.1 сая төгрөгөөр илүү, үйл ажиллагааны зардал 5,532.8 сая төгрөг, өр төлбөр 15,316.5 сая төгрөг, хөрөнгө оруулалт 11,283.2 сая төгрөгөөр дутуу тайлагнасан байна. | O22: 2 | P22: 33004.6 | Q22: 2 | R22: 33004.6 | S22: Шилэн дансыг улирал бүр толгой компанид тайлагнаж байгаа. Асуудлын бүртгэлд тусгасан тоонуудыг яаж гаргасан талаар тайлбар хэрэгтэй байна.
A23: 6 | B23: Эрдэнэс таван толгой ХК | C23: =+C24+C25 -> 0 | D23: =+D24+D25 -> 0 | E23: =+E24+E25 -> 0 | F23: =+F24+F25 -> 0 | G23: =+G24+G25 -> 0 | H23: =+H24+H25 -> 0 | I23: =+I24+I25 -> 0 | J23: =+J24+J25 -> 0 | ... R23: =+R24+R25 -> 402915.3
A24: 6.1 | B24: Шилэн дансны цахим хуудсанд эхний хагас жилийн хугацаанд 124 мэдээллээс 106 мэдээллийг хугацаанд нь, 1 мэдээллийг хугацаа хоцроон байршуулж, 7 мэдээлэл оруулаагүй, 106 мэдээллээс 10 мэдээллийг мэдээлэл байхгүйгээр тайлагнасан байна. Эхний хагас жилийн байдлаар “Төрийн өмчийн аж ахуйн нэгж байгууллагын зорилтот түвшин, гүйцэтгэл, хэтрэлт хэмнэлтийн шалтгаан тайлбарын хамт” гэсэн хэсэгт “мэдээлэл байхгүй” гэж оруулсан тул нийтэд мэдээлсэн мэдээлэлтэй тулган баталгаажуулах боломжгүй байна. | O24: 1 | Q24: 1 | R24: 0 | S24: Компани нь Нягтлан бодох бүртгэлийн тухай хуулийн 10.3-д заасны дагуу санхүүгийн тайланг жилд 2 удаа буюу хагас жил болон жилийн эцэст гарган Сангийн яаманд, Аж ахуйн нэгжийн орлогын албан татварын тухай хуулийн 26.1-д заасны дагуу орлогын албан татварын тайланг улирал бүрээр гарган татварын албанд хүргүүлдэг. Эдгээр хуулийн зохицуулалтын дагуу санхүүгийн тайлангийн үнэн зөв байдлын нийцлийг хангаж, холбогдох хууль тогтоомжид заасан хугацааг баримтлан мэдээллийг боловсруулдаг тул санхүүгийн зарим мэдээллийг сар бүрээр бэлтгэх боломжгүй болно. Компанийн 2025 оны эхний хагас жилийн төсвийн гүйцэтгэлийг санхүүгийн тайлан гарсны дараа буюу 2025 оны 8 дугар сарын 8-ны өдрийн дотор шилэн дансанд тайлбар, хавсралтын хамт байршуулан ажилласан. Тодруулбал, 1. 2025 оны 1 дүгээр улирлын зорилтот түвшингийн биелэлтийн гүйцэтгэлийг 2025 оны 05 дугаар сарын 07-ны өдөр; 2. 2025 оны 2 дугаар улирлын зорилтот түвшингийн биелэлтийн гүйцэтгэлийг 2025 оны 08 дугаар сарын 08-ны өдөр; 3. 2025 оны 3 дугаар улирлын зорилтот түвшингийн биелэлтийн гүйцэтгэлийг 2025 оны 11 дүгээр сарын 04-ны өдөр тус тус байршуулсан.
A25: 6.2 | B25: Тус компанийн 2025 оны эхний хагас жилийн санхүүгийн тайланд тусгасан санхүүгийн үзүүлэлт ХЭХ-д танилцуулсан мэдээлэлээс орлого 402,915.3 сая төгрөгөөр дутуу илэрхийлсэн байна. | K25: 1 | L25: 402915.3 | Q25: 1 | R25: 402915.3 | S25: Компанийн санхүүгийн орлогын дэлгэрэнгүй тайлан дахь "Орлогын нийт дүн"-д нүүрс борлуулалтын орлого буюу 2,473.9 тэрбум төгрөгөөс гадна Түрээсийн орлого, Хүүний орлого, Бусад орлого болон Гадаад валютын ханшийн зөрүүний олз багтсан байна. Тодруулбал 1. Түрээсийн орлого - 101.1 сая төгрөг; 2. Хүүний орлого - 41,945.0 сая төгрөг; 3. Бусад орлого - 304,091.6 сая төгрөг; 4. Гадаад валютын ханшийн зөрүүний олз - 56,777.6 сая төгрөг; Нийт - 402,915.3 сая төгрөг байна.
A26: 7 | B26: Гашуун Сухайт Автозам ХХК | C26: =+C27+C28 -> 0 | D26: =+D27+D28 -> 0 | E26: =+E27+E28 -> 0 | F26: =+F27+F28 -> 0 | G26: =+G27+G28 -> 0 | H26: =+H27+H28 -> 0 | I26: =+I27+I28 -> 0 | J26: =+J27+J28 -> 0 | ... R26: =+R27+R28 -> 209.6
A27: 7.1 | B27: Тус компани нь ХЭХ-д танилцуулсан мэдээллээс зардлын дүн санхүүгийн гүйцэтгэлээс 209.6 сая төгрөгөөр илүү илэрхийлсэн байна. | K27: 1 | L27: 209.6 | Q27: 1 | R27: 209.6 | S27: 2025 оны 12 сарын 31-ний өдрөөр Эрдэнэс Монгол нэгдэлд 339,714,236.74 төгрөгийн өглөгтэй гарсан. 2026 оны эхний хагас жилийн тайланд тус эхний үлдэгдлийг бууруулсан байна.
A28: 7.2 | B28: Шилэн дансны цахим хуудсанд эхний хагас жилийн хугацаанд 91 мэдээллээс 60 мэдээллийг хугацаанд нь, 3 мэдээллийг хугацаа хоцроон байршуулж, 28 мэдээллийг мэдээлэл байхгүйгээр тайлагнасан байна. Эхний хагас жилийн байдлаар “Төрийн өмчийн аж ахуйн нэгж байгууллагын зорилтот түвшин, гүйцэтгэл, хэтрэлт хэмнэлтийн шалтгаан тайлбарын хамт” гэсэн хэсэгт “мэдээлэл байхгүй” гэж оруулсан тул нийтэд мэдээлсэн мэдээлэлтэй тулган баталгаажуулах боломжгүй байна. | O28: 1 | Q28: 1 | R28: 0 | S28: “Нэгдлийн дотоод хяналт хэрэгжүүлэх жишиг аргачлал”-ын дагуу тайлангийн маягтыг боловсруулж, 2025 оны 1 дүгээр улирлын байдлаар хяналт хийлгэж, ШИЛЭН ДАНСНЫ ЦАХИМ ХУУДСАНД ТАВИХ МЭДЭЭЛЛИЙН АГУУЛГА, НИЙТЛЭГ СТАНДАРТЫГ ТОГТООХ ЖУРАМ 4.2-т зааснаар, шилэн дансны мэдээллийг оруулж байх талаар зөвлөмж ирүүлсэн. Тус зөвлөмж ирэхээс өмнө манай компани нь, Төрийн өмчит аж ахуйн нэгжийн оруулах мэдээллийн дагуу 25 мэдээлэл байршуулдаг бөгөөд тус мэдээллийн ихэнхи хувь нь манай компанийн үйл ажиллагаанд хамаарахгүй заалтууд байсан. Бид зөвлөмжийн дагуу 2025 оны 06 сараас сангийн яаманд хандан ШИЛЭН ДАНСНЫ ЦАХИМ ХУУДСАНД ТАВИХ МЭДЭЭЛЛИЙН АГУУЛГА, НИЙТЛЭГ СТАНДАРТЫГ ТОГТООХ ЖУРАМ 4.2-ийг 2025 оны 08 сараас тохиргоог хийлгэн шилэн дансны мэдээллийг 2025 оны 1 сараас нөхөн оруулж өнөөдрийн байдлаар ажиллаж байна.
A29: 8 | B29: Багануур ХК | C29: =+C30+C31 -> 1 | D29: =+D30+D31 -> 5862.9 | E29: =+E30+E31 -> 0 | F29: =+F30+F31 -> 0 | G29: =+G30+G31 -> 0 | H29: =+H30+H31 -> 0 | I29: =+I30+I31 -> 0 | J29: =+J30+J31 -> 0 | ... R29: =+R30+R31 -> 24495.4
A30: 8.1 | B30: Тус компанийн 2025 оны эхний хагас жилийн санхүүгийн тайланд тусгагдсан татварын дараах цэвэр ашгийн дүн ХЭХ-д танилцуулсан мэдээлэлд 194.1 сая төгрөг, авлага 5668.8 сая төгрөгөөр дутуу илэрхийлсэн байна | C30: 1 | D30: 5862.9 | Q30: 1 | R30: 5862.9 | S30: Компанийн 2025 оны эхний хагас жилийн санхүүгийн тайланд тусгагдсан татварын дараах цэвэр ашгийн дүн 1.903.2 сая төгрөгөөр тусгагдсан байна. Авлага 8.875.5 сая төгрөг байна /Хавсралт илгээлээ/
A31: 8.2 | B31: Шилэн дансны цахим хуудсанд эхний хагас жилийн хугацаанд 91 мэдээллээс 53 мэдээллийг хугацаанд нь, 3 мэдээллийг хугацаа хоцроон байршуулж, 35 мэдээллийг мэдээлэл байхгүйгээр тайлагнасан байна. Эхний хагас жилийн байдлаар санхүүгийн тайлангаас Шилэн дансны мэдээлэлд орлого 132.1 сая төгрөг, үйл ажиллагааны зардал 6,723.8 сая төгрөгөөр илүү, өр төлбөр 7,816.6, авлага 3,606.0 сая төгрөг, хөрөнгө оруулалт 354.0 сая төгрөгөөр дутуу тайлагнасан байна. | O31: 2 | P31: 18632.5 | Q31: 2 | R31: 18632.5 | S31: Шилэн дансны хуулиар сар бүрийн 8 дотор мэдээллээ явуулах шаарлагатай байдаг. Тухай бүрт санхүүгийн тайлан эцэслэгдээгүй байдаг тул хүлээгдэж буй гүйцэтгэлээр мэдээлэл оруулдагтай холбоотой зөрүү үүссэн байна.
A32: 9 | B32: Шивээ овоо ХК | C32: =+C33+C34 -> 0 | D32: =+D33+D34 -> 0 | E32: =+E33+E34 -> 0 | F32: =+F33+F34 -> 0 | G32: =+G33+G34 -> 0 | H32: =+H33+H34 -> 0 | I32: =+I33+I34 -> 0 | J32: =+J33+J34 -> 0 | ... R32: =+R33+R34 -> 19057.9
A33: 9.1 | B33: Тус компанийн 2025 оны эхний хагас жилийн санхүүгийн тайланд тусгасан санхүүгийн үзүүлэлтээс ХЭХ-д танилцуулсан мэдээлэлд хөрөнгө оруулалт 6,267.8 сая төгрөгөөр илүү танилцуулсан байна. | M33: 1 | N33: 6267.8 | Q33: 1 | R33: =+N33 -> 6267.8 | S33: 2025 оны 8 дугаар сарын 22-ны өдөр "Эрдэнэт ТӨҮГ"-т "Эрдэнэс Монгол" нэгдлийн охин компаниуд 2025 оны эхний хагас жилийн санхүүгийн тайлангийн хурал болсон. Тус хурал дээр танилцуулагдсан "Шивээ Овоо" ХК-ийн тайлангийн танилцуулгад 2025 оны хөрөнгө оруулалтын төлөвлөгөөний гүйцэтгэлийг 4,116.5 сая төгрөгөөр тайлагнасан болно. Тус хурал дээр танилцуулагдсан танилцуулгыг хавсралтаар хүргүүлэв.
A34: 9.2 | B34: Шилэн дансны цахим хуудсанд эхний хагас жилийн хугацаанд 91 мэдээллээс 90 мэдээллийг хугацаанд нь, 1 мэдээллийг мэдээлэл байхгүйгээр тайлагнасан байна. Эхний хагас жилийн байдлаар санхүүгийн тайлангаас Шилэн дансны мэдээлэлд орлого 80.2 сая төгрөг, өр төлбөр 5,351.0 сая төгрөг, авлага 3,187.0 сая төгрөгөөр дутуу, үйл ажиллагааны зардал 4,171.8 сая төгрөгөөр илүү мэдээлсэн байна. | O34: 2 | P34: 12790.1 | Q34: 2 | R34: 12790.1 | S34: Шилэн дансанд тухайн мэдээллүүдийг байршуулах өдрүүд сар бүрийн 8-ны өдрөөр тасалбар болдог. Гэвч манай компани болон харилцагч байгууллагуудын хоорондын тооцоо нийлсэн акт цаг хугацааны хувьд бүрэн бүрдэж амждаггүйгээс бүртгэл эцэслэгдэхгүй, орлого, зардал, авлага, өглөг илүү, дутуу бүртгэгдэх тохиолдол үүсч байна. Цаашид аудитаар өгөгдсөн зөвлөмжийг бүрэн хэрэгжүүлж ажиллахад анхаарч ажиллана.
A35: 10 | B35: "Эрдэнэс ҮТП" ХХК | C35: =+C36+C37 -> 0 | D35: =+D36+D37 -> 0 | E35: =+E36+E37 -> 0 | F35: =+F36+F37 -> 0 | G35: =+G36+G37 -> 0 | H35: =+H36+H37 -> 0 | I35: =+I36+I37 -> 0 | J35: =+J36+J37 -> 0 | ... R35: =+R36+R37 -> 1011.2
A36: 10.1 | B36: Тус компанийн 2025 оны эхний хагас жилийн санхүүгийн тайланд тусгасан санхүүгийн үзүүлэлтээс ХЭХ-д танилцуулсан мэдээлэлд үйл ажиллагааны зардал 46.5 сая төгрөг, хөрөнгө оруулалт 795.1 сая төгрөгөөр илүү танилцуулсан байна | K36: 1 | L36: 46.5 | M36: 1 | N36: 795.1 | Q36: 2 | R36: 841.6 | S36: Үйл ажиллагааны зардлын зөрүү нь 2025 оны эхний хагас жилийн мөнгөн гүйлгээний тайлангийн мөнгөн зарлагын 2,260.5 төгрөгийн дүнгээр танилцуулганд оруулсан. Хөрөнгө оруулалтын зөрүү нь дараах ажлуудын гэрээний төлбөрүүд эхний хагас жилд хийгдэхээр тооцож нэмж оруулж танилцуулсан. 1. Багануур ҮТП Нүүрс-химийн цогцолборын ерөнхий төлөвлөгөө, Нүүрс пиролизын үйлдвэрийн ТЭЗҮ боловсруулах гэрээний эхний төлбөр 486 сая төгрөг, 2. Хөтөл ҮТП-ийн Шохойн үйлдвэрийн технологийн түвшний үнэлгээ боловсруулах, батлуулах, шинжээчийн дүгнэлт гаргуулах гэрээний үлдэгдэл төлбөр 129.8 сая төгрөг, 3. Бор-Өндөр ҮТП-ийн Төмрийн хорголжийн үйлдвэрийн техник, технологийн түвшний үнэлгээ боловсруулах, батлуулах, шинжээчийн дүгнэлт гаргуулах гэрээний үлдэгдэл төлбөр 67.8 сая төгрөг, 4. Тавантолгой ҮТП-ийн Кокс-Эрчим хүчний үйлдвэрийн технологийн түвшний үнэлгээ боловсруулах, батлуулах, шинжээчийн дүгнэлт гаргуулах гэрээний үлдэгдэл төлбөр 111.3 сая төгрөг, нийт 795.1 сая төгрөг болно.
A37: 10.2 | B37: Шилэн дансны цахим хуудсанд эхний хагас жилийн хугацаанд 91 мэдээллээс 66 мэдээллийг хугацаанд нь, 9 мэдээллийг хугацаа хоцроон байршуулж, 13 мэдээлэл оруулаагүй, 3 мэдээллийг мэдээлэл байхгүйгээр тайлагнасан байна. Эхний хагас жилийн байдлаар санхүүгийн тайлангаас Шилэн дансны мэдээлэлд орлого 3.5 сая төгрөг, үйл ажиллагааны зардал 166.1 сая төгрөгөөр дутуу тайлагнасан байна. | O37: 2 | P37: 169.6 | Q37: 2 | R37: 169.6 | S37: Шилэн дансны цахим хуудсанд эхний хагас жилийн хугацаанд 91 мэдээллээс 83 мэдээллийг хугацаанд нь 8 мэдээллийг хугацаа хоцроон байршуулсан, 56 мэдээллийг байхгүй гэж тайлагнасан. Шилэн дансны хуулийн дагуу мэдээлэл байршуулах хугацаанд санхүүгийн тайлан баталгаажаагүй байсан тул орлого зарлагын дансны хаалтын дараагаар мэдээлэлд өөрчлөлт орсон.
A38: 11 | B38: "Монгол газрын тос боловсруулах үйлдвэр" ХХК | C38: =C39 -> 0 | D38: =D39 -> 0 | E38: =E39 -> 0 | F38: =F39 -> 0 | G38: =G39 -> 0 | H38: =H39 -> 0 | I38: =I39 -> 0 | J38: =J39 -> 0 | ... R38: =R39 -> 46631.2
A39: 11.2 | B39: Шилэн дансны цахим хуудсанд эхний хагас жилийн хугацаанд 91 мэдээллээс 83 мэдээллийг хугацаанд нь, 8 мэдээллийг мэдээлэл байхгүйгээр тайлагнасан байна. Эхний хагас жилийн байдлаар санхүүгийн тайлангаас Шилэн дансны мэдээлэлд орлого 1.5 сая төгрөг, нийт зардлыг 45,313.9 сая төгрөг, өр төлбөр 974.3 сая төгрөгөөр дутуу, авлага 341.5 сая төгрөгөөр илүү илэрхийлсэн байна. | O39: 2 | P39: 46631.2 | Q39: 2 | R39: 46631.2 | S39: Тайлан гаргахаас өмнө шилэн дансны мэдээллийг хугацаандаа шивэх гээд урьдчилж оруулсан дүн байдаг болохоор санхүүгийн тайлантай зөрж байгаа.
A40: 12 | B40: "Эрдэнэс Оюу толгой" ХХК | C40: =+C41+C42+C43 -> 0 | D40: =+D41+D42+D43 -> 0 | E40: =+E41+E42+E43 -> 0 | F40: =+F41+F42+F43 -> 0 | G40: =+G41+G42+G43 -> 0 | H40: =+H41+H42+H43 -> 0 | I40: =+I41+I42+I43 -> 0 | J40: =+J41+J42+J43 -> 0 | ... R40: =+R41+R42+R43 -> 3527.1
A41: 12.1 | B41: Тус компанийн 2025 оны эхний хагас жилийн санхүүгийн тайланд тусгасан санхүүгийн үзүүлэлт ХЭХ-д танилцуулсан мэдээлэлээс орлого 56.9 сая төгрөг, зардал 117.8 сая төгрөгөөр дутуу танилцуулсан байна. | K41: 1 | L41: 174.7 | Q41: 1 | R41: 174.7 | S41: Засгийн газрын хэрэг эрхлэх газар 2025 оны эхний хагас жилийн санхүүгийн тайланг танилцуулахдаа урьдчилж гарсан зардал болох 117.8 сая төгрөгийн гэрээт ажлын зардлыг дараагийн 3.4-р улиралд зорилтот түвшний гүйцэтгэлээр тайлагнасан.
A42: 12.2 | B42: Он дамнасан хөрөнгө оруулалтын зардал буюу албан оффисын худалдан авалтын үлдэгдэл санхүүжилт болох 2,474.0 сая төгрөгийн зардлыг ТУЗ-д санал оруулж батлуулаагүй байна. | M42: 1 | N42: 2474 | Q42: 1 | R42: 2474 | S42: Тус компани нь 2024 оны “Эрдэнэс Монгол” ХХК-ны ТУЗ-ийн хууль журмын хүрээнд хөрөнгө оруулалтын төлөвлөсний дагуу оффисын байр тендер зарлаж гэрээ байгуулсан боловч ашиглалтад орох хугацаа манайхаас үл хамааран хойшлогдож жил дамжсан, Нягтлан бодох бүртгэлийн тухай хуулийн 13 дугаар зүйлийн 13.7-д Анхан шатны баримтын бүрдэлгүй ажил, гүйлгээг бүртгэх, санхүүгийн тайланд тусгахыг хориглоно гэж заасан тул 30% төлбөрийг нь ашиглалтад орж үл хөдлөхийн гэрчилгээ авснаар баталгаажин төлөгдөх 2.5 тэрбумын өглөгийг тусгах боломжгүй байсан тул мөнгөн хөрөнгийн үлдэгдлээр шийдвэрлэсэн.
...

Sheet Асуудлын нэгтгэл
S1: Дотоод аудитын БА-2025/11 дугаартай тайлангийн хавсралт
A2: НЭГДЛИЙН ОХИН ХАРААТ КОМПАНИД ХИЙСЭН АУДИТЫН АСУУДЛЫН НЭГТГЭЛИЙН ХАРИУ ТАЙЛБАР
R3: /сая төгрөг/
A4: № | B4: Илэрсэн асуудлын товч утга | C4: Санхүүгийн тайлангийн үзүүлэлт | E4: Авлага, өр төлбөр | G4: Санхүүгийн шинжилгээний үр дүн | I4: Уулын ажил | K4: ЭЗҮҮ | M4: Хөрөнгө оруулалт | O4: Шилэн данс | Q4: Нийт дүн | S4: Хариу тайлбар
C5: Асуудлын тоо | D5: Мөнгөн дүн | E5: Асуудлын тоо | F5: Мөнгөн дүн | G5: Асуудлын тоо | H5: Мөнгөн дүн | I5: Асуудлын тоо | J5: Мөнгөн дүн | K5: Асуудлын тоо | L5: Мөнгөн дүн | M5: Асуудлын тоо | N5: Мөнгөн дүн | O5: Асуудлын тоо | P5: Мөнгөн дүн | Q5: Асуудлын тоо | R5: Мөнгөн дүн
A6: 1 | B6: Эрдэнэт Үйлдвэр ТӨҮГ | C6: =+C7+C8+C9+C10 -> 1 | D6: =+D7+D8+D9+D10 -> 176584 | E6: =+E7+E8+E9+E10 -> 0 | F6: =+F7+F8+F9+F10 -> 0 | G6: =+G7+G8+G9+G10 -> 0 | H6: =+H7+H8+H9+H10 -> 0 | I6: =+I7+I8+I9+I10 -> 0 | J6: =+J7+J8+J9+J10 -> 0 | ... R6: =+R7+R8+R9+R10 -> 450513.2
A7: 1.1 | B7: Санхүүгийн бүртгэлд шилжүүлсэн үндсэн хөрөнгийн дүнг татвар ногдуулах зорилгоор үйлдвэрийн орлогоор бүртгэсэн ба үүний улмаас үйлдвэрийн орлого 84,087.6 сая төгрөгөөр, үйлдвэрийн зардал 92,496.4 сая төгрөгөөр тус тус үндэслэлгүйгээр нэмэгдсэн байна. /Шилжүүлсэн хөрөнгийг үндсэн хөрөнгө бор/шилжүүлсний гарзаар 92,496.4 сая төгрөгөөр бүртгэсэн/ | C7: 1 | D7: 176584 | Q7: 1 | R7: 176584 | S7: Нэмэгдсэн өртгийн албан татварын тухай хуулийн 13.9-д "Бараа, ажил, үйлчилгээг үйлдвэрлэлийн дотоод эргэлтэд ашигласнаас бусад хэлбэрээр бусдад үнэ төлбөргүй шилжүүлсэн буюу хувийнхаа хэрэгцээнд ашигласан бол нэмэгдсэн өртгийн албан татвараас чөлөөлөхгүй", 4.1.2-т ""бараа" гэж мөнгөн хөрөнгөнөөс бусад бүх төрлийн хөрөнгийг" гэж тус тус заасны дагуу орлогоор хүлээн зөвшөөрч бүртгэсэн.
A8: 1.2 | B8: Үйлдвэрийн эхний хагас жилийн зардлын төсөвлөсөн дүнгээс үйл ажиллагааны зардал 43,580.0 сая төгрөгөөр, үйл ажиллагааны бус зардал 24,407.3 сая төгрөгөөр, нийгмийн цехүүдийн болон нийгэм соёлын арга хэмжээний зардал 48,057.0 сая төгрөгөөр тус тус хэтрүүлэн зарцуулсан байна. | K8: 1 | L8: 116044.3 | Q8: 1 | R8: 116044.3 | S8: Эрдэнэс монгол ХХК-ийн ТУЗ-ийн 2025 оны 10 дугаар сарын 07-ны өдрийн 93 дугаар тогтоолоор "Эрдэнэт үйлдвэр" ТӨҮГ-ын 2025 оны эдийн засгийн үндсэн үзүүлэлт, зорилтот түвшин, төсөв, хөрөнгө оруулалтын төлөвлөгөөнд өөрчлөлт оруулсан.
A9: 1.3 | B9: Татварын болон санхүүгийн тайлангийн зарим үзүүлэлтүүд зөрүүтэй илэрхийлэгдсэн байна. (Татварын болон санхүүгийн 2025 оны эхний хагас жилийн тайлангаас үндсэн ба үндсэн бус үйл ажиллагааны орлого 526.5 сая төгрөгөөр, зардал 157,358.4 сая төгрөгөөр зөрүүтэй илэрхийлсэн байна.) | K9: 1 | L9: 157884.9 | Q9: 1 | R9: 157884.9 | S9: Бусад борлуулалтын орлогын дүн нь үйлдвэрийн цехүүдийн гадны байгууллагад үзүүлсэн ажил үйлчилгээний борлуулалтын 5109-00 данс, гадны байгууллагад худалдсан бараа материалын борлуулалтын 5111-00 дансууд нэгтгэгддэг ба эдгээр орлогод өртөг тооцогддог тул туслах үйлдвэрлэл, үйлчилгээний орлогоор тооцсон.
A10: 1.4 | B10: Шилэн дансны цахим хуудсанд эхний хагас жилийн хугацаанд 91 мэдээллээс 85 мэдээллийг хугацаанд нь, 6 мэдээллийг хугацаа хоцроон байршуулж, 85 мэдээллээс 8 мэдээллийг мэдээлэл байхгүйгээр тайлагнасан байна. Эхний хагас жилийн байдлаар “Төрийн өмчийн аж ахуйн нэгж байгууллагын зорилтот түвшин, гүйцэтгэл, хэтрэлт хэмнэлтийн шалтгаан тайлбарын хамт” гэсэн хэсэгт “мэдээлэл байхгүй” гэж оруулсан тул нийтэд мэдээлсэн мэдээлэлтэй тулган баталгаажуулах боломжгүй байна. | O10: 1 | Q10: 1 | R10: 0 | S10: Үйлдвэрийн газрын 2025 оны хөрөнгө оруулалтын төлөвлөгөөг баталсан "Эрдэнэс Монгол" ХХК-ийн ТУЗ-ын тогтоол 2024 оны 12 дугаар сарын 19-ний өдрөөр гарсан боловч эцэслэн баталгаажуулалт нь 2025 оны 01 дүгээр сарын 10-ны өдрөөс хойш буюу 2025 оны 02 дугаар сарын 10-ны өдөр хийгдсэн. Тухайн баталгаажуулалт хийгдсэн даруйд хөрөнгийн зардал, хөрөнгө оруулалтын төсөл, арга хэмжээний төлөвлөгөө, концессын зүйлийн жагсаалтын төлөвлөгөө болон 1-р сарын гүйцэтгэлийг шилэн дансны цахим системд байршуулсан болно. Үйлдвэрийн газрын худалдан авах ажиллагааны төлөвлөгөө нь батлагдсан хөрөнгө оруулалтын төлөвлөгөө, зорилтот түвшин, бизнес төлөвлөгөөнд үндэслэн боловсруулагддаг. Хөрөнгө оруулалтын төлөвлөгөө, зорилтот түвшин, бизнес төлөвлөгөө хугацаа хоцорч батлагдсантай холбоотойгоор хойшлогдож боловсруулагдаж, батлагдсан. ХАА-ны төлөвлөгөө tender.gov.mn-д нийтлэгдсэн даруйд шилэн дансны цахим системд байршуулсан болно. Үйлдвэрийн газрын 2024 оны зорилтот түвшний гүйцэтгэл нь жилийн эцсийн санхүүгийн тайлан эцэслэн гарсны дараа албажиж гардаг тул үүнийг хуулийн хугацаанд байршуулах боломжгүй юм. Иймд бид хавсралтаар албан ёсны мэдээллийг нөхөж оруулсан болно.
A11: 2 | B11: Дарханы Төмөрлөгийн Үйлдвэр ТӨХХК | C11: =+C12+C13 -> 0 | D11: =+D12+D13 -> 0 | E11: =+E12+E13 -> 0 | F11: =+F12+F13 -> 0 | G11: =+G12+G13 -> 0 | H11: =+H12+H13 -> 0 | I11: =+I12+I13 -> 0 | J11: =+J12+J13 -> 0 | ... R11: =+R12+R13 -> 49314.8
A12: 2.1 | B12: Тус компанийн 2025 оны эхний хагас жилийн санхүүгийн тайланд тусгагдсан санхүүгийн мэдээлэл ХЭХ-д танилцуулсан мэдээлэлээс нийт орлого 4,883.8 сая төгрөгөөр дутуу, зардал 2,525.9 сая төгрөгөөр илүү илэрхийлсэн байна | K12: 1 | L12: 7418.4 | Q12: 1 | R12: 7418.4 | S12: Дарханы төмөрлөгийн үйлдвэр ХХК нь төсөв, төлөвлөгөө, гүйцэтгэлийг тайланг боловсруулахдаа Эрдэнэс Монгол ХХК-аас ирүүлсэн "Нэгдлийн хуулийн этгээдийн зорилтот түвшин, төсөв, хөрөнгө оруулалтын төлөвлөгөө, тодотголын төсөл боловсруулах аргачлал"-ийг мөрдлөг болгон тайлагнадаг. Дарханы төмөрлөгийн үйлдвэрийн 2025 оны хагас жилийн ХЭХ-ийн танилцуулгад нийт орлогод бүтээгдэхүүний борлуулалтын орлого 282,389.9 тэрбум төгрөг, түрээсийн орлого 257.9 сая төгрөг, хүүгийн орлого 847.5 сая төгрөг, бусад орлого 413.3 сая төгрөг нийт орлогыг 284.9 тэрбум төгрөгөөр танилцуулсан. Гадаад валютын ханшийн олз 4,883.8 сая төгрөгийг үйл ажиллагааны бус ашгаар зорилтот түвшинд оруулж нийт орлогод оруулаагүй. Нийт зардлыг үйлдвэрлэл, үйл ажиллагааны нийт зардлаар буюу 244,857.9 сая төгрөгөөр танилцуулсан бөгөөд үүнээс борлуулсан бүтээгдэхүүний өртөг 242,374.0 сая төгрөг, бэлэн бүтээгдэхүүнрүү шилжих өртөг 2,483.9 сая төгрөг байна. Тус аргачлалын маягт№1-ын дагуу эдийн засгийн үндсэн үзүүлэлт, зорилтот түвшнийг бэлтгэн үүний дагуу тоон үзүүлэлтүүдийг ХЭХ-д танилцуулсан.
A13: 2.2 | B13: Шилэн дансны цахим хуудсанд эхний хагас жилийн хугацаанд 91 мэдээллээс 78 мэдээллийг хугацаанд нь, 4 мэдээллийг хугацаа хоцроон байршуулж, 9 мэдээллийг мэдээлэл байхгүйгээр тайлагнасан байна. | O13: 2 | P13: 41896.4 | Q13: 2 | R13: 41896.4 | S13: Дарханы төмөрлөгийн үйлдвэр ХХК-ийн эдийн засгийн үндсэн үзүүлэлт, зорилтот түвшин, хөрөнгө оруулалтын төлөвлөгөө, төсөв нь 2024 оны 12 дугаар сарын 19-ны өдөр Эрдэнэс Монгол ХХК-ийн ТУЗ-ийн хурлаар орсон. Төсөв, хөрөнгө оруулалтын тогтоол 2025 оны 01 дүгээр сарын 20-ны өдөр албажин ирсэн. Шилэн дансны мэдээллийг жил бүрийн 01 дүгээр сарын 10-ны дотор оруулах заалттай боловч төсөв төлөвлөгөө баталгаажин ирээгүйн улмаас мэдээллийг хугацаанд нь оруулаагүй хугацаа хоцроосон. 2025 оны төсөв, хөрөнгө оруулалтын төлөвлөгөөнд 2025 оны эхний хагас жилийн байдлаар өөрчлөлт ороогүй тул төлөвлөгөөнд өөрчлөлт ороогүйгээр тайлагнасан.
A14: 3 | B14: Цемент шохой ТӨХХК | C14: =C15+C16 -> 0 | D14: =D15+D16 -> 0 | E14: =E15+E16 -> 0 | F14: =F15+F16 -> 0 | G14: =G15+G16 -> 0 | H14: =H15+H16 -> 0 | I14: =I15+I16 -> 0 | J14: =J15+J16 -> 0 | ... R14: =R15+R16 -> 407667.4
A15: 3.1 | B15: 2025 оны эхний хагас жилийн үйл ажиллагааны нийт зардлын дүн ХЭХ-д танилцуулсан мэдээлэл, ТТ-02-ийн мэдээлэл зөрүүтэй байна | K15: 1 | L15: 1444.5 | Q15: 1 | R15: 1444.5 | S15: 2 удаа мэдэгдсэн ирүүлээгүй.
A16: 3.2 | B16: Шилэн дансны цахим хуудсанд эхний хагас жилийн хугацаанд 91 мэдээллээс 65 мэдээллийг хугацаанд нь, 6 мэдээллийг хугацаа хоцроон байршуулж, 20 мэдээллийг мэдээлэл байхгүйгээр тайлагнасан байна. Эхний хагас жилийн байдлаар санхүүгийн тайлангаас Шилэн дансны мэдээлэлд орлого 620.1 сая төгрөг, авлага 46,870.2 сая төгрөгөөр илүү, үйл ажиллагааны зардал 4,231.2 сая төгрөг, өглөг 354,501.4 сая төгрөгөөр дутуу тайлагнасан байна. | O16: 2 | P16: 406222.9 | Q16: 2 | R16: 406222.9
A17: 4 | B17: Эрдэнэс критикал менералс ТӨҮГ | C17: =+C18 -> 0 | D17: =+D18 -> 0 | E17: =+E18 -> 0 | F17: =+F18 -> 0 | G17: =+G18 -> 0 | H17: =+H18 -> 0 | I17: =+I18 -> 0 | J17: =+J18 -> 0 | ... R17: =+R18 -> 94723.5
A18: 4.1 | B18: Шилэн дансны цахим хуудсанд эхний хагас жилийн хугацаанд 91 мэдээллээс 82 мэдээллийг хугацаанд нь, 3 мэдээллийг хугацаа хоцроон байршуулж, 6 мэдээллийг мэдээлэл байхгүйгээр тайлагнасан байна. Эхний хагас жилийн байдлаар санхүүгийн тайлангаас Шилэн дансны мэдээлэлд нийт орлого 4,611.4 сая төгрөг, өр төлбөр 47,616.1 сая төгрөг, авлага 19,294.4 сая төгрөг, хөрөнгө оруулалт 6,575.2 сая төгрөгөөр дутуу, үйл ажиллагааны зардал 16,626.4 сая төгрөгөөр илүү тайлагнасан байна. | O18: 2 | P18: 94723.5 | Q18: 2 | R18: 94723.5 | S18: """Эрдэнэс критикал минералс"" ТӨҮГ нь тухайн тайлант хугацааны (сар бүр) мэдээллийг шилэн дансанд дараа сарын 8-ны өдрийн дотор байршуулж байна. Дээрх хугацаанд манай байгууллагын орлогын тайлан, төсвийн гүйцэтгэл, ашиг алдагдлын тайлан бүрэн гарах боломжгүй байдаг тул тухайн тайлант хугацааны орлого, өр төлбөр, авлага, хөрөнгө оруулалт, зардал, ашиг алдагдал зэргийг урьдчилан тооцоолж хүлээгдэж буй гүйцэтгэлээр мэдээллийг байршуулж байгаа болно. Жич : төсвийн байгууллага, төрийн сантай адил сар бүрийн эцэст төсвийн хэлбэлзэл татаж тайлан гаргах боломжгүй, мөн санхүүгийн тайланг сар бүр гаргадаггүй болно. "
A19: 5 | B19: Эрдэнэс Алт Ресурс ХХК | C19: =+C20+C21+C22 -> 1 | D19: =+D20+D21+D22 -> 39887.1 | E19: =+E20+E21+E22 -> 0 | F19: =+F20+F21+F22 -> 0 | G19: =+G20+G21+G22 -> 0 | H19: =+H20+H21+H22 -> 0 | I19: =+I20+I21+I22 -> 0 | J19: =+J20+J21+J22 -> 0 | ... R19: =+R20+R21+R22 -> 75213
A20: 5.1 | B20: Тус компани нь 2025 оны эхний хагас жилийн санхүүгийн тайлангаас ХЭХ-д танилцуулсан мэдээлэлээс орлого 2,321.3 сая төгрөгөөр дутуу илэрхийлсэн байна | K20: 1 | L20: 2321.3 | Q20: 1 | R20: 2321.3 | S20: орлогыг дутуу илэрхийлсэн мэдээлэл байхгүй 2,321.3 сая төгрөгийг яаж гаргасан талаар мэдээлэл авах хэрэгтэй байна.
A21: 5.2 | B21: Тус компани нь 2025 оны эхний хагас жилийн санхүүгийн тайлангаас ХЭХ-д танилцуулсан мэдээлэлээс нийт хөрөнгө 2,343.2 сая төгрөгөөр, өр төлбөр 37,543.9 сая төгрөгөөр зөрүүтэй илэрхийлсэн байна. | C21: 1 | D21: 39887.1 | Q21: 1 | R21: 39887.1 | S21: мэдээллийн дэлгэрэнгүйтэй танилцах шаардлагаатай байна.
A22: 5.3 | B22: Шилэн дансны цахим хуудсанд эхний хагас жилийн хугацаанд 91 мэдээллээс 79 мэдээллийг хугацаанд нь, 6 мэдээллийг хугацаа хоцроон байршуулж, 6 мэдээллийг мэдээлэл байхгүйгээр тайлагнасан байна. Эхний хагас жилийн байдлаар санхүүгийн тайлангаас Шилэн данс мэдээлэл орлого 16.0 сая төгрөг, авлага 856.1 сая төгрөгөөр илүү, үйл ажиллагааны зардал 5,532.8 сая төгрөг, өр төлбөр 15,316.5 сая төгрөг, хөрөнгө оруулалт 11,283.2 сая төгрөгөөр дутуу тайлагнасан байна. | O22: 2 | P22: 33004.6 | Q22: 2 | R22: 33004.6 | S22: Шилэн дансыг улирал бүр толгой компанид тайлагнаж байгаа. Асуудлын бүртгэлд тусгасан тоонуудыг яаж гаргасан талаар тайлбар хэрэгтэй байна.
A23: 6 | B23: Эрдэнэс таван толгой ХК | C23: =+C24+C25 -> 0 | D23: =+D24+D25 -> 0 | E23: =+E24+E25 -> 0 | F23: =+F24+F25 -> 0 | G23: =+G24+G25 -> 0 | H23: =+H24+H25 -> 0 | I23: =+I24+I25 -> 0 | J23: =+J24+J25 -> 0 | ... R23: =+R24+R25 -> 402915.3
A24: 6.1 | B24: Шилэн дансны цахим хуудсанд эхний хагас жилийн хугацаанд 124 мэдээллээс 106 мэдээллийг хугацаанд нь, 1 мэдээллийг хугацаа хоцроон байршуулж, 7 мэдээлэл оруулаагүй, 106 мэдээллээс 10 мэдээллийг мэдээлэл байхгүйгээр тайлагнасан байна. Эхний хагас жилийн байдлаар “Төрийн өмчийн аж ахуйн нэгж байгууллагын зорилтот түвшин, гүйцэтгэл, хэтрэлт хэмнэлтийн шалтгаан тайлбарын хамт” гэсэн хэсэгт “мэдээлэл байхгүй” гэж оруулсан тул нийтэд мэдээлсэн мэдээлэлтэй тулган баталгаажуулах боломжгүй байна. | O24: 1 | Q24: 1 | R24: 0 | S24: Компани нь Нягтлан бодох бүртгэлийн тухай хуулийн 10.3-д заасны дагуу санхүүгийн тайланг жилд 2 удаа буюу хагас жил болон жилийн эцэст гарган Сангийн яаманд, Аж ахуйн нэгжийн орлогын албан татварын тухай хуулийн 26.1-д заасны дагуу орлогын албан татварын тайланг улирал бүрээр гарган татварын албанд хүргүүлдэг. Эдгээр хуулийн зохицуулалтын дагуу санхүүгийн тайлангийн үнэн зөв байдлын нийцлийг хангаж, холбогдох хууль тогтоомжид заасан хугацааг баримтлан мэдээллийг боловсруулдаг тул санхүүгийн зарим мэдээллийг сар бүрээр бэлтгэх боломжгүй болно. Компанийн 2025 оны эхний хагас жилийн төсвийн гүйцэтгэлийг санхүүгийн тайлан гарсны дараа буюу 2025 оны 8 дугар сарын 8-ны өдрийн дотор шилэн дансанд тайлбар, хавсралтын хамт байршуулан ажилласан. Тодруулбал, 1. 2025 оны 1 дүгээр улирлын зорилтот түвшингийн биелэлтийн гүйцэтгэлийг 2025 оны 05 дугаар сарын 07-ны өдөр; 2. 2025 оны 2 дугаар улирлын зорилтот түвшингийн биелэлтийн гүйцэтгэлийг 2025 оны 08 дугаар сарын 08-ны өдөр; 3. 2025 оны 3 дугаар улирлын зорилтот түвшингийн биелэлтийн гүйцэтгэлийг 2025 оны 11 дүгээр сарын 04-ны өдөр тус тус байршуулсан.
A25: 6.2 | B25: Тус компанийн 2025 оны эхний хагас жилийн санхүүгийн тайланд тусгасан санхүүгийн үзүүлэлт ХЭХ-д танилцуулсан мэдээлэлээс орлого 402,915.3 сая төгрөгөөр дутуу илэрхийлсэн байна. | K25: 1 | L25: 402915.3 | Q25: 1 | R25: 402915.3 | S25: Компанийн санхүүгийн орлогын дэлгэрэнгүй тайлан дахь "Орлогын нийт дүн"-д нүүрс борлуулалтын орлого буюу 2,473.9 тэрбум төгрөгөөс гадна Түрээсийн орлого, Хүүний орлого, Бусад орлого болон Гадаад валютын ханшийн зөрүүний олз багтсан байна. Тодруулбал 1. Түрээсийн орлого - 101.1 сая төгрөг; 2. Хүүний орлого - 41,945.0 сая төгрөг; 3. Бусад орлого - 304,091.6 сая төгрөг; 4. Гадаад валютын ханшийн зөрүүний олз - 56,777.6 сая төгрөг; Нийт - 402,915.3 сая төгрөг байна.
A26: 7 | B26: Гашуун Сухайт Автозам ХХК | C26: =+C27+C28 -> 0 | D26: =+D27+D28 -> 0 | E26: =+E27+E28 -> 0 | F26: =+F27+F28 -> 0 | G26: =+G27+G28 -> 0 | H26: =+H27+H28 -> 0 | I26: =+I27+I28 -> 0 | J26: =+J27+J28 -> 0 | ... R26: =+R27+R28 -> 209.6
A27: 7.1 | B27: Тус компани нь ХЭХ-д танилцуулсан мэдээллээс зардлын дүн санхүүгийн гүйцэтгэлээс 209.6 сая төгрөгөөр илүү илэрхийлсэн байна. | K27: 1 | L27: 209.6 | Q27: 1 | R27: 209.6 | S27: 2025 оны 12 сарын 31-ний өдрөөр Эрдэнэс Монгол нэгдэлд 339,714,236.74 төгрөгийн өглөгтэй гарсан. 2026 оны эхний хагас жилийн тайланд тус эхний үлдэгдлийг бууруулсан байна.
A28: 7.2 | B28: Шилэн дансны цахим хуудсанд эхний хагас жилийн хугацаанд 91 мэдээллээс 60 мэдээллийг хугацаанд нь, 3 мэдээллийг хугацаа хоцроон байршуулж, 28 мэдээллийг мэдээлэл байхгүйгээр тайлагнасан байна. Эхний хагас жилийн байдлаар “Төрийн өмчийн аж ахуйн нэгж байгууллагын зорилтот түвшин, гүйцэтгэл, хэтрэлт хэмнэлтийн шалтгаан тайлбарын хамт” гэсэн хэсэгт “мэдээлэл байхгүй” гэж оруулсан тул нийтэд мэдээлсэн мэдээлэлтэй тулган баталгаажуулах боломжгүй байна. | O28: 1 | Q28: 1 | R28: 0 | S28: “Нэгдлийн дотоод хяналт хэрэгжүүлэх жишиг аргачлал”-ын дагуу тайлангийн маягтыг боловсруулж, 2025 оны 1 дүгээр улирлын байдлаар хяналт хийлгэж, ШИЛЭН ДАНСНЫ ЦАХИМ ХУУДСАНД ТАВИХ МЭДЭЭЛЛИЙН АГУУЛГА, НИЙТЛЭГ СТАНДАРТЫГ ТОГТООХ ЖУРАМ 4.2-т зааснаар, шилэн дансны мэдээллийг оруулж байх талаар зөвлөмж ирүүлсэн. Тус зөвлөмж ирэхээс өмнө манай компани нь, Төрийн өмчит аж ахуйн нэгжийн оруулах мэдээллийн дагуу 25 мэдээлэл байршуулдаг бөгөөд тус мэдээллийн ихэнхи хувь нь манай компанийн үйл ажиллагаанд хамаарахгүй заалтууд байсан. Бид зөвлөмжийн дагуу 2025 оны 06 сараас сангийн яаманд хандан ШИЛЭН ДАНСНЫ ЦАХИМ ХУУДСАНД ТАВИХ МЭДЭЭЛЛИЙН АГУУЛГА, НИЙТЛЭГ СТАНДАРТЫГ ТОГТООХ ЖУРАМ 4.2-ийг 2025 оны 08 сараас тохиргоог хийлгэн шилэн дансны мэдээллийг 2025 оны 1 сараас нөхөн оруулж өнөөдрийн байдлаар ажиллаж байна.
A29: 8 | B29: Багануур ХК | C29: =+C30+C31 -> 1 | D29: =+D30+D31 -> 5862.9 | E29: =+E30+E31 -> 0 | F29: =+F30+F31 -> 0 | G29: =+G30+G31 -> 0 | H29: =+H30+H31 -> 0 | I29: =+I30+I31 -> 0 | J29: =+J30+J31 -> 0 | ... R29: =+R30+R31 -> 24495.4
A30: 8.1 | B30: Тус компанийн 2025 оны эхний хагас жилийн санхүүгийн тайланд тусгагдсан татварын дараах цэвэр ашгийн дүн ХЭХ-д танилцуулсан мэдээлэлд 194.1 сая төгрөг, авлага 5668.8 сая төгрөгөөр дутуу илэрхийлсэн байна | C30: 1 | D30: 5862.9 | Q30: 1 | R30: 5862.9 | S30: Компанийн 2025 оны эхний хагас жилийн санхүүгийн тайланд тусгагдсан татварын дараах цэвэр ашгийн дүн 1.903.2 сая төгрөгөөр тусгагдсан байна. Авлага 8.875.5 сая төгрөг байна /Хавсралт илгээлээ/
A31: 8.2 | B31: Шилэн дансны цахим хуудсанд эхний хагас жилийн хугацаанд 91 мэдээллээс 53 мэдээллийг хугацаанд нь, 3 мэдээллийг хугацаа хоцроон байршуулж, 35 мэдээллийг мэдээлэл байхгүйгээр тайлагнасан байна. Эхний хагас жилийн байдлаар санхүүгийн тайлангаас Шилэн дансны мэдээлэлд орлого 132.1 сая төгрөг, үйл ажиллагааны зардал 6,723.8 сая төгрөгөөр илүү, өр төлбөр 7,816.6, авлага 3,606.0 сая төгрөг, хөрөнгө оруулалт 354.0 сая төгрөгөөр дутуу тайлагнасан байна. | O31: 2 | P31: 18632.5 | Q31: 2 | R31: 18632.5 | S31: Шилэн дансны хуулиар сар бүрийн 8 дотор мэдээллээ явуулах шаарлагатай байдаг. Тухай бүрт санхүүгийн тайлан эцэслэгдээгүй байдаг тул хүлээгдэж буй гүйцэтгэлээр мэдээлэл оруулдагтай холбоотой зөрүү үүссэн байна.
A32: 9 | B32: Шивээ овоо ХК | C32: =+C33+C34 -> 0 | D32: =+D33+D34 -> 0 | E32: =+E33+E34 -> 0 | F32: =+F33+F34 -> 0 | G32: =+G33+G34 -> 0 | H32: =+H33+H34 -> 0 | I32: =+I33+I34 -> 0 | J32: =+J33+J34 -> 0 | ... R32: =+R33+R34 -> 19057.9
A33: 9.1 | B33: Тус компанийн 2025 оны эхний хагас жилийн санхүүгийн тайланд тусгасан санхүүгийн үзүүлэлтээс ХЭХ-д танилцуулсан мэдээлэлд хөрөнгө оруулалт 6,267.8 сая төгрөгөөр илүү танилцуулсан байна. | M33: 1 | N33: 6267.8 | Q33: 1 | R33: =+N33 -> 6267.8 | S33: 2025 оны 8 дугаар сарын 22-ны өдөр "Эрдэнэт ТӨҮГ"-т "Эрдэнэс Монгол" нэгдлийн охин компаниуд 2025 оны эхний хагас жилийн санхүүгийн тайлангийн хурал болсон. Тус хурал дээр танилцуулагдсан "Шивээ Овоо" ХК-ийн тайлангийн танилцуулгад 2025 оны хөрөнгө оруулалтын төлөвлөгөөний гүйцэтгэлийг 4,116.5 сая төгрөгөөр тайлагнасан болно. Тус хурал дээр танилцуулагдсан танилцуулгыг хавсралтаар хүргүүлэв.
A34: 9.2 | B34: Шилэн дансны цахим хуудсанд эхний хагас жилийн хугацаанд 91 мэдээллээс 90 мэдээллийг хугацаанд нь, 1 мэдээллийг мэдээлэл байхгүйгээр тайлагнасан байна. Эхний хагас жилийн байдлаар санхүүгийн тайлангаас Шилэн дансны мэдээлэлд орлого 80.2 сая төгрөг, өр төлбөр 5,351.0 сая төгрөг, авлага 3,187.0 сая төгрөгөөр дутуу, үйл ажиллагааны зардал 4,171.8 сая төгрөгөөр илүү мэдээлсэн байна. | O34: 2 | P34: 12790.1 | Q34: 2 | R34: 12790.1 | S34: Шилэн дансанд тухайн мэдээллүүдийг байршуулах өдрүүд сар бүрийн 8-ны өдрөөр тасалбар болдог. Гэвч манай компани болон харилцагч байгууллагуудын хоорондын тооцоо нийлсэн акт цаг хугацааны хувьд бүрэн бүрдэж амждаггүйгээс бүртгэл эцэслэгдэхгүй, орлого, зардал, авлага, өглөг илүү, дутуу бүртгэгдэх тохиолдол үүсч байна. Цаашид аудитаар өгөгдсөн зөвлөмжийг бүрэн хэрэгжүүлж ажиллахад анхаарч ажиллана.
A35: 10 | B35: "Эрдэнэс ҮТП" ХХК | C35: =+C36+C37 -> 0 | D35: =+D36+D37 -> 0 | E35: =+E36+E37 -> 0 | F35: =+F36+F37 -> 0 | G35: =+G36+G37 -> 0 | H35: =+H36+H37 -> 0 | I35: =+I36+I37 -> 0 | J35: =+J36+J37 -> 0 | ... R35: =+R36+R37 -> 1011.2
A36: 10.1 | B36: Тус компанийн 2025 оны эхний хагас жилийн санхүүгийн тайланд тусгасан санхүүгийн үзүүлэлтээс ХЭХ-д танилцуулсан мэдээлэлд үйл ажиллагааны зардал 46.5 сая төгрөг, хөрөнгө оруулалт 795.1 сая төгрөгөөр илүү танилцуулсан байна | K36: 1 | L36: 46.5 | M36: 1 | N36: 795.1 | Q36: 2 | R36: 841.6 | S36: Үйл ажиллагааны зардлын зөрүү нь 2025 оны эхний хагас жилийн мөнгөн гүйлгээний тайлангийн мөнгөн зарлагын 2,260.5 төгрөгийн дүнгээр танилцуулганд оруулсан. Хөрөнгө оруулалтын зөрүү нь дараах ажлуудын гэрээний төлбөрүүд эхний хагас жилд хийгдэхээр тооцож нэмж оруулж танилцуулсан. 1. Багануур ҮТП Нүүрс-химийн цогцолборын ерөнхий төлөвлөгөө, Нүүрс пиролизын үйлдвэрийн ТЭЗҮ боловсруулах гэрээний эхний төлбөр 486 сая төгрөг, 2. Хөтөл ҮТП-ийн Шохойн үйлдвэрийн технологийн түвшний үнэлгээ боловсруулах, батлуулах, шинжээчийн дүгнэлт гаргуулах гэрээний үлдэгдэл төлбөр 129.8 сая төгрөг, 3. Бор-Өндөр ҮТП-ийн Төмрийн хорголжийн үйлдвэрийн техник, технологийн түвшний үнэлгээ боловсруулах, батлуулах, шинжээчийн дүгнэлт гаргуулах гэрээний үлдэгдэл төлбөр 67.8 сая төгрөг, 4. Тавантолгой ҮТП-ийн Кокс-Эрчим хүчний үйлдвэрийн технологийн түвшний үнэлгээ боловсруулах, батлуулах, шинжээчийн дүгнэлт гаргуулах гэрээний үлдэгдэл төлбөр 111.3 сая төгрөг, нийт 795.1 сая төгрөг болно.
A37: 10.2 | B37: Шилэн дансны цахим хуудсанд эхний хагас жилийн хугацаанд 91 мэдээллээс 66 мэдээллийг хугацаанд нь, 9 мэдээллийг хугацаа хоцроон байршуулж, 13 мэдээлэл оруулаагүй, 3 мэдээллийг мэдээлэл байхгүйгээр тайлагнасан байна. Эхний хагас жилийн байдлаар санхүүгийн тайлангаас Шилэн дансны мэдээлэлд орлого 3.5 сая төгрөг, үйл ажиллагааны зардал 166.1 сая төгрөгөөр дутуу тайлагнасан байна. | O37: 2 | P37: 169.6 | Q37: 2 | R37: 169.6 | S37: Шилэн дансны цахим хуудсанд эхний хагас жилийн хугацаанд 91 мэдээллээс 83 мэдээллийг хугацаанд нь 8 мэдээллийг хугацаа хоцроон байршуулсан, 56 мэдээллийг байхгүй гэж тайлагнасан. Шилэн дансны хуулийн дагуу мэдээлэл байршуулах хугацаанд санхүүгийн тайлан баталгаажаагүй байсан тул орлого зарлагын дансны хаалтын дараагаар мэдээлэлд өөрчлөлт орсон.
A38: 11 | B38: "Монгол газрын тос боловсруулах үйлдвэр" ХХК | C38: =+C39+C40 -> 0 | D38: =+D39+D40 -> 0 | E38: =+E39+E40 -> 0 | F38: =+F39+F40 -> 0 | G38: =+G39+G40 -> 0 | H38: =+H39+H40 -> 0 | I38: =+I39+I40 -> 0 | J38: =+J39+J40 -> 0 | ... R38: =+R39+R40 -> 46632.8
A39: 11.1 | B39: Тус компанийн 2025 оны эхний хагас жилийн санхүүгийн тайланд тусгасан санхүүгийн үзүүлэлтээс Татварын албаны цахим тайланд орлогын дүнг 1.6 сая төгрөгөөр илүү илэрхийлсэн байна. | K39: 1 | L39: 1.6 | Q39: 1 | R39: 1.6 | S39: Татварын тайлан дээр 1,568,587.47 бодит бус орлогын дүн тавигдсан учир тухайн дүнгээр зөрнө.
A40: 11.2 | B40: Шилэн дансны цахим хуудсанд эхний хагас жилийн хугацаанд 91 мэдээллээс 83 мэдээллийг хугацаанд нь, 8 мэдээллийг мэдээлэл байхгүйгээр тайлагнасан байна. Эхний хагас жилийн байдлаар санхүүгийн тайлангаас Шилэн дансны мэдээлэлд орлого 1.5 сая төгрөг, нийт зардлыг 45,313.9 сая төгрөг, өр төлбөр 974.3 сая төгрөгөөр дутуу, авлага 341.5 сая төгрөгөөр илүү илэрхийлсэн байна. | O40: 2 | P40: 46631.2 | Q40: 2 | R40: 46631.2 | S40: Тайлан гаргахаас өмнө шилэн дансны мэдээллийг хугацаандаа шивэх гээд урьдчилж оруулсан дүн байдаг болохоор санхүүгийн тайлантай зөрж байгаа.
...

Sheet Асуудлын бүртгэл
A2: ....... ХХК-ИЙН 2025 ОНЫ ЭХНИЙ ХАГАС ЖИЛИЙН ҮЙЛ АЖИЛЛАГААНЫ ТАЙЛАНГИЙН САНХҮҮГИЙН МЭДЭЭЛЛИЙН БАТАЛГААЖУУЛАЛТЫН АУДИТААР ИЛЭРСЭН АСУУДЛЫН ХАРИУ ТАЙЛБАР
E4: /сая төгрөг/
A5: № | B5: Илэрсэн асуудлын товч утга | C5: мөнгөн дүн | D5: Шалгуур | E5: Хариу тайлбар
A6: ='Асуудлын нэгтгэл'!A6 -> 1 | B6: Шилэн дансны цахим хуудсанд эхний хагас жилийн хугацаанд 91 мэдээллээс 85 мэдээллийг хугацаанд нь, 6 мэдээллийг хугацаа хоцроон байршуулж, 85 мэдээллээс 8 мэдээллийг мэдээлэл байхгүйгээр тайлагнасан байна. Эхний хагас жилийн байдлаар “Төрийн өмчийн аж ахуйн нэгж байгууллагын зорилтот түвшин, гүйцэтгэл, хэтрэлт хэмнэлтийн шалтгаан тайлбарын хамт” гэсэн хэсэгт “мэдээлэл байхгүй” гэж оруулсан тул нийтэд мэдээлсэн мэдээлэлтэй тулган баталгаажуулах боломжгүй байна. | D6: Шилэн дансны тухай хуулийн 4.1.1-д "Мэдээлэл үнэн зөв, бодитой, иж бүрэн байх", 4.1.3-т "Тогтоосон хугацаанд тогтмол, шуурхай мэдээлдэг байх"
A7: 2
A9: ='Асуудлын нэгтгэл'!A17 -> 4 | B9: ='Асуудлын нэгтгэл'!B17 -> Эрдэнэс критикал менералс ТӨҮГ
A10: ='Асуудлын нэгтгэл'!A18 -> 4.1 | B10: ='Асуудлын нэгтгэл'!B18 -> Шилэн дансны цахим хуудсанд эхний хагас жилийн хугацаанд 91 мэдээллээс 82 мэдээллийг хугацаанд нь, 3 мэдээллийг хугацаа хоцроон байршуулж, 6 мэдээллийг мэдээлэл байхгүйгээр тайлагнасан байна. Эхний хагас жилийн байдлаар санхүүгийн тайлангаас Шилэн дансны мэдээлэлд нийт орлого 4,611.4 сая төгрөг, өр төлбөр 47,616.1 сая төгрөг, авлага 19,294.4 сая төгрөг, хөрөнгө оруулалт 6,575.2 сая төгрөгөөр дутуу, үйл ажиллагааны зардал 16,626.4 сая төгрөгөөр илүү тайлагнасан байна.
A16: Дүн
B19: Гарын үсэг
